<?xml version="1.0" encoding="utf-8"?>
<!-- This URDF was automatically created by SolidWorks to URDF Exporter! Originally created by Stephen Brawner (brawner@gmail.com) 
     Commit Version: 1.6.0-4-g7f85cfe  Build Version: 1.6.7995.38578
     For more information, please see http://wiki.ros.org/sw_urdf_exporter -->
<robot
  name="TLR7">
  <link
    name="Base_Link">
    <inertial>
      <origin
        xyz="0.005748 -0.0030713 0.022212"
        rpy="0 0 0" />
      <mass
        value="1.18" />
      <inertia
        ixx="0.0011328"
        ixy="-6.9016E-05"
        ixz="4.1381E-06"
        iyy="0.0013187"
        iyz="5.5069E-08"
        izz="0.0018102" />
    </inertial>
    <visual>
      <origin
        xyz="0 0 0"
        rpy="0 0 0" />
      <geometry>
        <mesh
          filename="package://TLR7/meshes/Base_Link.STL" />
      </geometry>
      <material
        name="">
        <color
          rgba="0.75294 0.75294 0.75294 1" />
      </material>
    </visual>
    <collision>
      <origin
        xyz="0 0 0"
        rpy="0 0 0" />
      <geometry>
        <mesh
          filename="package://TLR7/meshes/Base_Link.STL" />
      </geometry>
    </collision>
  </link>
  <link
    name="L1_thigh_Link">
    <inertial>
      <origin
        xyz="0.021433 0.016145 -0.00023498"
        rpy="0 0 0" />
      <mass
        value="0.21728" />
      <inertia
        ixx="8.0555E-05"
        ixy="2.6054E-08"
        ixz="3.3478E-06"
        iyy="0.0004103"
        iyz="-3.5646E-08"
        izz="0.00034326" />
    </inertial>
    <visual>
      <origin
        xyz="0 0 0"
        rpy="0 0 0" />
      <geometry>
        <mesh
          filename="package://TLR7/meshes/L1_thigh_Link.STL" />
      </geometry>
      <material
        name="">
        <color
          rgba="0.75294 0.75294 0.75294 1" />
      </material>
    </visual>
    <collision>
      <origin
        xyz="0 0 0"
        rpy="0 0 0" />
      <geometry>
        <mesh
          filename="package://TLR7/meshes/L1_thigh_Link.STL" />
      </geometry>
    </collision>
  </link>
  <joint
    name="L1_thigh_joint"
    type="revolute">
    <origin
      xyz="0.10392 0 0.0018"
      rpy="0 0 0" />
    <parent
      link="Base_Link" />
    <child
      link="L1_thigh_Link" />
    <axis
      xyz="0 1 0" />
    <limit
      lower="-1.04"
      upper="2.08"
      effort="30"
      velocity="15" />
  </joint>
  <link
    name="L1_shin_Link">
    <inertial>
      <origin
        xyz="0.039171 -0.00010523 0.010727"
        rpy="0 0 0" />
      <mass
        value="0.06867" />
      <inertia
        ixx="6.8345E-06"
        ixy="3.5866E-13"
        ixz="-2.5094E-06"
        iyy="6.2678E-05"
        iyz="9.1817E-14"
        izz="5.8738E-05" />
    </inertial>
    <visual>
      <origin
        xyz="0 0 0"
        rpy="0 0 0" />
      <geometry>
        <mesh
          filename="package://TLR7/meshes/L1_shin_Link.STL" />
      </geometry>
      <material
        name="">
        <color
          rgba="0.75294 0.75294 0.75294 1" />
      </material>
    </visual>
    <collision>
      <origin
        xyz="0 0 0"
        rpy="0 0 0" />
      <geometry>
        <mesh
          filename="package://TLR7/meshes/L1_shin_Link.STL" />
      </geometry>
    </collision>
  </link>
  <joint
    name="L1_shin_joint"
    type="revolute">
    <origin
      xyz="0.18315 0 -0.0069273"
      rpy="0 0 0" />
    <parent
      link="L1_thigh_Link" />
    <child
      link="L1_shin_Link" />
    <axis
      xyz="0 1 0" />
    <limit
      lower="0"
      upper="2.71"
      effort="30"
      velocity="15" />
  </joint>
  <link
    name="L2_thigh_Link">
    <inertial>
      <origin
        xyz="-0.024699 0.010489 -0.00023498"
        rpy="0 0 0" />
      <mass
        value="0.21728" />
      <inertia
        ixx="0.00032789"
        ixy="0.00014277"
        ixz="-1.643E-06"
        iyy="0.00016297"
        iyz="2.9171E-06"
        izz="0.00034326" />
    </inertial>
    <visual>
      <origin
        xyz="0 0 0"
        rpy="0 0 0" />
      <geometry>
        <mesh
          filename="package://TLR7/meshes/L2_thigh_Link.STL" />
      </geometry>
      <material
        name="">
        <color
          rgba="0.75294 0.75294 0.75294 1" />
      </material>
    </visual>
    <collision>
      <origin
        xyz="0 0 0"
        rpy="0 0 0" />
      <geometry>
        <mesh
          filename="package://TLR7/meshes/L2_thigh_Link.STL" />
      </geometry>
    </collision>
  </link>
  <joint
    name="L2_thigh_joint"
    type="revolute">
    <origin
      xyz="-0.051961 0.09 0.0018"
      rpy="0 0 0" />
    <parent
      link="Base_Link" />
    <child
      link="L2_thigh_Link" />
    <axis
      xyz="-0.86603 -0.5 0" />
    <limit
      lower="-1.04"
      upper="2.08"
      effort="30"
      velocity="15" />
  </joint>
  <link
    name="L2_shin_Link">
    <inertial>
      <origin
        xyz="-0.019494 0.033976 0.010727"
        rpy="0 0 0" />
      <mass
        value="0.06867" />
      <inertia
        ixx="4.8717E-05"
        ixy="2.4181E-05"
        ixz="1.2547E-06"
        iyy="2.0795E-05"
        iyz="-2.1732E-06"
        izz="5.8738E-05" />
    </inertial>
    <visual>
      <origin
        xyz="0 0 0"
        rpy="0 0 0" />
      <geometry>
        <mesh
          filename="package://TLR7/meshes/L2_shin_Link.STL" />
      </geometry>
      <material
        name="">
        <color
          rgba="0.75294 0.75294 0.75294 1" />
      </material>
    </visual>
    <collision>
      <origin
        xyz="0 0 0"
        rpy="0 0 0" />
      <geometry>
        <mesh
          filename="package://TLR7/meshes/L2_shin_Link.STL" />
      </geometry>
    </collision>
  </link>
  <joint
    name="L2_shin_joint"
    type="revolute">
    <origin
      xyz="-0.091574 0.15861 -0.0069273"
      rpy="0 0 0" />
    <parent
      link="L2_thigh_Link" />
    <child
      link="L2_shin_Link" />
    <axis
      xyz="-0.86603 -0.5 0" />
    <limit
      lower="0"
      upper="2.71"
      effort="30"
      velocity="15" />
  </joint>
  <link
    name="L3_thigh_Link">
    <inertial>
      <origin
        xyz="0 0 0"
        rpy="0 0 0" />
      <mass
        value="0" />
      <inertia
        ixx="0"
        ixy="0"
        ixz="0"
        iyy="0"
        iyz="0"
        izz="0" />
    </inertial>
    <visual>
      <origin
        xyz="0 0 0"
        rpy="0 0 0" />
      <geometry>
        <mesh
          filename="package://TLR7/meshes/L3_thigh_Link.STL" />
      </geometry>
      <material
        name="">
        <color
          rgba="1 1 1 1" />
      </material>
    </visual>
    <collision>
      <origin
        xyz="0 0 0"
        rpy="0 0 0" />
      <geometry>
        <mesh
          filename="package://TLR7/meshes/L3_thigh_Link.STL" />
      </geometry>
    </collision>
  </link>
  <joint
    name="L3_thigh_joint"
    type="revolute">
    <origin
      xyz="-0.051962 -0.09 0.0018"
      rpy="0 0 0" />
    <parent
      link="Base_Link" />
    <child
      link="L3_thigh_Link" />
    <axis
      xyz="0.86603 -0.5 0" />
    <limit
      lower="-1.04"
      upper="2.08"
      effort="30"
      velocity="15" />
  </joint>
  <link
    name="L3_shin_Link">
    <inertial>
      <origin
        xyz="-0.019677 -0.033871 0.010727"
        rpy="0 0 0" />
      <mass
        value="0.06867" />
      <inertia
        ixx="4.8717E-05"
        ixy="-2.4181E-05"
        ixz="1.2547E-06"
        iyy="2.0795E-05"
        iyz="2.1732E-06"
        izz="5.8738E-05" />
    </inertial>
    <visual>
      <origin
        xyz="0 0 0"
        rpy="0 0 0" />
      <geometry>
        <mesh
          filename="package://TLR7/meshes/L3_shin_Link.STL" />
      </geometry>
      <material
        name="">
        <color
          rgba="0.75294 0.75294 0.75294 1" />
      </material>
    </visual>
    <collision>
      <origin
        xyz="0 0 0"
        rpy="0 0 0" />
      <geometry>
        <mesh
          filename="package://TLR7/meshes/L3_shin_Link.STL" />
      </geometry>
    </collision>
  </link>
  <joint
    name="L3_shin_joint"
    type="revolute">
    <origin
      xyz="-0.091574 -0.15861 -0.0069273"
      rpy="0 0 0" />
    <parent
      link="L3_thigh_Link" />
    <child
      link="L3_shin_Link" />
    <axis
      xyz="0.86603 -0.5 0" />
    <limit
      lower="0"
      upper="2.71"
      effort="30"
      velocity="15" />
  </joint>
</robot>